<?xml version="1.0" encoding="utf-8" ?>
<!-- This URDF was automatically created by SolidWorks to URDF Exporter! Originally created by Stephen Brawner (brawner@gmail.com) 
     Commit Version: 1.6.0-4-g7f85cfe  Build Version: 1.6.7995.38578
     For more information, please see http://wiki.ros.org/sw_urdf_exporter -->
<robot name="biped_gen">
    <link name="base_link">
        <inertial>
            <origin xyz="-0.0131642143292668 -0.00101855461920026 0.120968817067497" rpy="0 0 0" />
            <mass value="17.7538790248349" />
            <inertia ixx="0.109513413578879" ixy="-3.84263402985455E-06" ixz="0.00207222923626091" iyy="0.0639718644540958" iyz="5.94596039827144E-06" izz="0.0796086142464904" />
        </inertial>
        <visual>
            <origin xyz="0 0 0" rpy="0 0 0" />
            <geometry>
                <mesh filename="package://biped_gen/meshes/base_link.STL" />
            </geometry>
            <material name="">
                <color rgba="0.898039215686275 0.917647058823529 0.929411764705882 1" />
            </material>
        </visual>
        <collision>
            <origin xyz="0 0 0" rpy="0 0 0" />
            <geometry>
                <mesh filename="package://biped_gen/meshes/base_link.STL" />
            </geometry>
        </collision>
    </link>
    <link name="l_arm_pitch">
        <inertial>
            <origin xyz="0.0146835191418715 -0.0166604103758634 -6.82857133371129E-05" rpy="0 0 0" />
            <mass value="0.165847319965906" />
            <inertia ixx="0.0002674432873971" ixy="-2.5654089149164E-05" ixz="-1.72966133127553E-07" iyy="0.000125796784291983" iyz="-1.66717296343013E-06" izz="0.000196186976742156" />
        </inertial>
        <visual>
            <origin xyz="0 0 0" rpy="0 0 0" />
            <geometry>
                <mesh filename="package://biped_gen/meshes/l_arm_pitch.STL" />
            </geometry>
            <material name="">
                <color rgba="1 1 1 1" />
            </material>
        </visual>
        <collision>
            <origin xyz="0 0 0" rpy="0 0 0" />
            <geometry>
                <mesh filename="package://biped_gen/meshes/l_arm_pitch.STL" />
            </geometry>
        </collision>
    </link>
    <joint name="l_arm_pitch" type="continuous">
        <origin xyz="-0.0175475823124921 0.254700000000031 0.324500000000024" rpy="0 0 0" />
        <parent link="base_link" />
        <child link="l_arm_pitch" />
        <axis xyz="0 -1 0" />
    </joint>
    <link name="l_arm_roll">
        <inertial>
            <origin xyz="0.0222872651779299 0.0156945544195473 -0.0202262244341484" rpy="0 0 0" />
            <mass value="0.141426581413056" />
            <inertia ixx="0.000160370067223081" ixy="6.30811840859269E-06" ixz="-1.13259246453495E-05" iyy="0.000262365778589962" iyz="3.14941259087024E-05" izz="0.00023601403628197" />
        </inertial>
        <visual>
            <origin xyz="0 0 0" rpy="0 0 0" />
            <geometry>
                <mesh filename="package://biped_gen/meshes/l_arm_roll.STL" />
            </geometry>
            <material name="">
                <color rgba="1 1 1 1" />
            </material>
        </visual>
        <collision>
            <origin xyz="0 0 0" rpy="0 0 0" />
            <geometry>
                <mesh filename="package://biped_gen/meshes/l_arm_roll.STL" />
            </geometry>
        </collision>
    </link>
    <joint name="l_arm_roll" type="continuous">
        <origin xyz="0 0 0" rpy="0 0 0" />
        <parent link="l_arm_pitch" />
        <child link="l_arm_roll" />
        <axis xyz="1 0 0" />
    </joint>
    <link name="l_arm_yaw">
        <inertial>
            <origin xyz="6.16940440451783E-05 0.00525815062784063 -0.128821944854616" rpy="0 0 0" />
            <mass value="0.147794102819133" />
            <inertia ixx="7.00575957554699E-05" ixy="-6.81658291272877E-10" ixz="2.69427050743199E-10" iyy="8.53612265336777E-05" iyz="6.95899873075699E-06" izz="8.82223899453285E-05" />
        </inertial>
        <visual>
            <origin xyz="0 0 0" rpy="0 0 0" />
            <geometry>
                <mesh filename="package://biped_gen/meshes/l_arm_yaw.STL" />
            </geometry>
            <material name="">
                <color rgba="1 1 1 1" />
            </material>
        </visual>
        <collision>
            <origin xyz="0 0 0" rpy="0 0 0" />
            <geometry>
                <mesh filename="package://biped_gen/meshes/l_arm_yaw.STL" />
            </geometry>
        </collision>
    </link>
    <joint name="l_arm_yaw" type="continuous">
        <origin xyz="0 0 0" rpy="0 0 0" />
        <parent link="l_arm_roll" />
        <child link="l_arm_yaw" />
        <axis xyz="0 0 -1" />
    </joint>
    <link name="l_forearm_pitch">
        <inertial>
            <origin xyz="-1.4281929799409E-05 0.00938313949959718 -0.0522687552263489" rpy="0 0 0" />
            <mass value="0.170164726102009" />
            <inertia ixx="9.558084476069E-05" ixy="-4.53863490387433E-08" ixz="5.39342118513253E-08" iyy="0.000126326373178391" iyz="-9.58160032696958E-06" izz="0.000121032474884238" />
        </inertial>
        <visual>
            <origin xyz="0 0 0" rpy="0 0 0" />
            <geometry>
                <mesh filename="package://biped_gen/meshes/l_forearm_pitch.STL" />
            </geometry>
            <material name="">
                <color rgba="1 1 1 1" />
            </material>
        </visual>
        <collision>
            <origin xyz="0 0 0" rpy="0 0 0" />
            <geometry>
                <mesh filename="package://biped_gen/meshes/l_forearm_pitch.STL" />
            </geometry>
        </collision>
    </link>
    <joint name="l_forearm_pitch" type="continuous">
        <origin xyz="0 0 -0.163599999999998" rpy="0 0 0" />
        <parent link="l_arm_yaw" />
        <child link="l_forearm_pitch" />
        <axis xyz="0 -1 0" />
    </joint>
    <link name="l_hand_yaw">
        <inertial>
            <origin xyz="0.000113133463122583 0.00969227839919062 0.0817960696431681" rpy="0 0 0" />
            <mass value="0.157336288737043" />
            <inertia ixx="7.64923984145487E-05" ixy="8.51098127601464E-09" ixz="-1.4070355859132E-08" iyy="0.000122231132554914" iyz="1.11226968994633E-06" izz="8.44935061342021E-05" />
        </inertial>
        <visual>
            <origin xyz="0 0 0" rpy="0 0 0" />
            <geometry>
                <mesh filename="package://biped_gen/meshes/l_hand_yaw.STL" />
            </geometry>
            <material name="">
                <color rgba="1 1 1 1" />
            </material>
        </visual>
        <collision>
            <origin xyz="0 0 0" rpy="0 0 0" />
            <geometry>
                <mesh filename="package://biped_gen/meshes/l_hand_yaw.STL" />
            </geometry>
        </collision>
    </link>
    <joint name="l_hand_yaw" type="continuous">
        <origin xyz="0 0 -0.191049997298861" rpy="0 0 0" />
        <parent link="l_forearm_pitch" />
        <child link="l_hand_yaw" />
        <axis xyz="0 0 -1" />
    </joint>
    <link name="l_hand_pitch">
        <inertial>
            <origin xyz="0.00810609786663821 0.00489663150092601 0.00622488608908427" rpy="0 0 0" />
            <mass value="0.0853891779246004" />
            <inertia ixx="4.77321490368476E-05" ixy="3.05261917457107E-06" ixz="4.77827164947654E-06" iyy="3.43814769749139E-05" iyz="-4.59311499587155E-06" izz="2.49955336560135E-05" />
        </inertial>
        <visual>
            <origin xyz="0 0 0" rpy="0 0 0" />
            <geometry>
                <mesh filename="package://biped_gen/meshes/l_hand_pitch.STL" />
            </geometry>
            <material name="">
                <color rgba="1 1 1 1" />
            </material>
        </visual>
        <collision>
            <origin xyz="0 0 0" rpy="0 0 0" />
            <geometry>
                <mesh filename="package://biped_gen/meshes/l_hand_pitch.STL" />
            </geometry>
        </collision>
    </link>
    <joint name="l_hand_pitch" type="continuous">
        <origin xyz="0 0 0" rpy="0 0 0" />
        <parent link="l_hand_yaw" />
        <child link="l_hand_pitch" />
        <axis xyz="0 1 0" />
    </joint>
    <link name="l_hand_roll">
        <inertial>
            <origin xyz="0.0055750097939089 0.00647363667890594 -0.0826245715087526" rpy="0 0 0" />
            <mass value="0.156748589916411" />
            <inertia ixx="8.04371746531483E-05" ixy="2.770174858381E-07" ixz="-4.63354764745673E-06" iyy="0.000116536814280971" iyz="1.04534418501281E-05" izz="0.000111690600253046" />
        </inertial>
        <visual>
            <origin xyz="0 0 0" rpy="0 0 0" />
            <geometry>
                <mesh filename="package://biped_gen/meshes/l_hand_roll.STL" />
            </geometry>
            <material name="">
                <color rgba="1 1 1 1" />
            </material>
        </visual>
        <collision>
            <origin xyz="0 0 0" rpy="0 0 0" />
            <geometry>
                <mesh filename="package://biped_gen/meshes/l_hand_roll.STL" />
            </geometry>
        </collision>
    </link>
    <joint name="l_hand_roll" type="continuous">
        <origin xyz="0 0 0" rpy="0 0 0" />
        <parent link="l_hand_pitch" />
        <child link="l_hand_roll" />
        <axis xyz="1 0 0" />
    </joint>
    <link name="r_arm_pitch">
        <inertial>
            <origin xyz="0.0146743511434554 0.0168298008224051 -8.16711977456031E-05" rpy="0 0 0" />
            <mass value="0.165729466195453" />
            <inertia ixx="0.000267364314112701" ixy="2.58822573731612E-05" ixz="-1.74450019197634E-07" iyy="0.000125724274127356" iyz="1.71810516637517E-06" izz="0.000196179895851995" />
        </inertial>
        <visual>
            <origin xyz="0 0 0" rpy="0 0 0" />
            <geometry>
                <mesh filename="package://biped_gen/meshes/r_arm_pitch.STL" />
            </geometry>
            <material name="">
                <color rgba="1 1 1 1" />
            </material>
        </visual>
        <collision>
            <origin xyz="0 0 0" rpy="0 0 0" />
            <geometry>
                <mesh filename="package://biped_gen/meshes/r_arm_pitch.STL" />
            </geometry>
        </collision>
    </link>
    <joint name="r_arm_pitch" type="continuous">
        <origin xyz="-0.0175475823119764 -0.254700000000003 0.324500000000024" rpy="0 0 0" />
        <parent link="base_link" />
        <child link="r_arm_pitch" />
        <axis xyz="0 -1 0" />
    </joint>
    <link name="r_arm_roll">
        <inertial>
            <origin xyz="0.0223009070030529 -0.0156950170482436 -0.0202307747650334" rpy="0 0 0" />
            <mass value="0.141493827304592" />
            <inertia ixx="0.00016058853411588" ixy="-6.25733649402466E-06" ixz="-1.13236198708706E-05" iyy="0.000262566981542989" iyz="-3.14930415013909E-05" izz="0.000236151535262186" />
        </inertial>
        <visual>
            <origin xyz="0 0 0" rpy="0 0 0" />
            <geometry>
                <mesh filename="package://biped_gen/meshes/r_arm_roll.STL" />
            </geometry>
            <material name="">
                <color rgba="1 1 1 1" />
            </material>
        </visual>
        <collision>
            <origin xyz="0 0 0" rpy="0 0 0" />
            <geometry>
                <mesh filename="package://biped_gen/meshes/r_arm_roll.STL" />
            </geometry>
        </collision>
    </link>
    <joint name="r_arm_roll" type="continuous">
        <origin xyz="0 0 0" rpy="0 0 0" />
        <parent link="r_arm_pitch" />
        <child link="r_arm_roll" />
        <axis xyz="1 0 0" />
    </joint>
    <link name="r_arm_yaw">
        <inertial>
            <origin xyz="-4.82749435400213E-05 -0.0052581506278393 -0.128821944854617" rpy="0 0 0" />
            <mass value="0.147794102819133" />
            <inertia ixx="7.00575957554697E-05" ixy="-6.81658260938682E-10" ixz="-2.69427064597612E-10" iyy="8.53612265336775E-05" iyz="-6.95899873075696E-06" izz="8.82223899453284E-05" />
        </inertial>
        <visual>
            <origin xyz="0 0 0" rpy="0 0 0" />
            <geometry>
                <mesh filename="package://biped_gen/meshes/r_arm_yaw.STL" />
            </geometry>
            <material name="">
                <color rgba="1 1 1 1" />
            </material>
        </visual>
        <collision>
            <origin xyz="0 0 0" rpy="0 0 0" />
            <geometry>
                <mesh filename="package://biped_gen/meshes/r_arm_yaw.STL" />
            </geometry>
        </collision>
    </link>
    <joint name="r_arm_yaw" type="continuous">
        <origin xyz="0 0 0" rpy="0 0 0" />
        <parent link="r_arm_roll" />
        <child link="r_arm_yaw" />
        <axis xyz="0 0 -1" />
    </joint>
    <link name="r_forearm_pitch">
        <inertial>
            <origin xyz="-0.000127232990745116 -0.00951602649232586 -0.0522687552263488" rpy="0 0 0" />
            <mass value="0.170164726102011" />
            <inertia ixx="9.55808447606916E-05" ixy="-4.53863489774233E-08" ixz="-5.41060583443891E-08" iyy="0.000126326373178394" iyz="9.40982665987077E-06" izz="0.00012103247488424" />
        </inertial>
        <visual>
            <origin xyz="0 0 0" rpy="0 0 0" />
            <geometry>
                <mesh filename="package://biped_gen/meshes/r_forearm_pitch.STL" />
            </geometry>
            <material name="">
                <color rgba="1 1 1 1" />
            </material>
        </visual>
        <collision>
            <origin xyz="0 0 0" rpy="0 0 0" />
            <geometry>
                <mesh filename="package://biped_gen/meshes/r_forearm_pitch.STL" />
            </geometry>
        </collision>
    </link>
    <joint name="r_forearm_pitch" type="continuous">
        <origin xyz="0 0 -0.1636" rpy="0 0 0" />
        <parent link="r_arm_yaw" />
        <child link="r_forearm_pitch" />
        <axis xyz="0 1 0" />
    </joint>
    <link name="r_hand_yaw">
        <inertial>
            <origin xyz="-0.000113133331993445 -0.0097448351680483 0.0817960724173413" rpy="0 0 0" />
            <mass value="0.157336288734482" />
            <inertia ixx="7.64923982725728E-05" ixy="8.51115986496426E-09" ixz="1.40703608309957E-08" iyy="0.000122231132626729" iyz="-1.11226978982942E-06" izz="8.44935061081861E-05" />
        </inertial>
        <visual>
            <origin xyz="0 0 0" rpy="0 0 0" />
            <geometry>
                <mesh filename="package://biped_gen/meshes/r_hand_yaw.STL" />
            </geometry>
            <material name="">
                <color rgba="1 1 1 1" />
            </material>
        </visual>
        <collision>
            <origin xyz="0 0 0" rpy="0 0 0" />
            <geometry>
                <mesh filename="package://biped_gen/meshes/r_hand_yaw.STL" />
            </geometry>
        </collision>
    </link>
    <joint name="r_hand_yaw" type="continuous">
        <origin xyz="0 0 -0.191050000125729" rpy="0 0 0" />
        <parent link="r_forearm_pitch" />
        <child link="r_hand_yaw" />
        <axis xyz="0 0 -1" />
    </joint>
    <link name="r_hand_pitch">
        <inertial>
            <origin xyz="0.00735986990228184 -0.0047523802551166 0.00605888061339196" rpy="0 0 0" />
            <mass value="0.0853891534309893" />
            <inertia ixx="4.77321358097824E-05" ixy="-2.99709432812988E-06" ixz="4.71488437974188E-06" iyy="3.42470226388499E-05" iyz="4.61094199971347E-06" izz="2.51299600072388E-05" />
        </inertial>
        <visual>
            <origin xyz="0 0 0" rpy="0 0 0" />
            <geometry>
                <mesh filename="package://biped_gen/meshes/r_hand_pitch.STL" />
            </geometry>
            <material name="">
                <color rgba="1 1 1 1" />
            </material>
        </visual>
        <collision>
            <origin xyz="0 0 0" rpy="0 0 0" />
            <geometry>
                <mesh filename="package://biped_gen/meshes/r_hand_pitch.STL" />
            </geometry>
        </collision>
    </link>
    <joint name="r_hand_pitch" type="continuous">
        <origin xyz="0 0 0" rpy="0 0 0" />
        <parent link="r_hand_yaw" />
        <child link="r_hand_pitch" />
        <axis xyz="0 1 0" />
    </joint>
    <link name="r_hand_roll">
        <inertial>
            <origin xyz="0.0045944493552252 -0.00586927010446042 -0.0836324643988434" rpy="0 0 0" />
            <mass value="0.305839717252105" />
            <inertia ixx="0.000160651543151659" ixy="-5.37963063503334E-07" ixz="-9.47669219939636E-06" iyy="0.000229393712149694" iyz="-2.08351527945055E-05" izz="0.000219277776699058" />
        </inertial>
        <visual>
            <origin xyz="0 0 0" rpy="0 0 0" />
            <geometry>
                <mesh filename="package://biped_gen/meshes/r_hand_roll.STL" />
            </geometry>
            <material name="">
                <color rgba="1 1 1 1" />
            </material>
        </visual>
        <collision>
            <origin xyz="0 0 0" rpy="0 0 0" />
            <geometry>
                <mesh filename="package://biped_gen/meshes/r_hand_roll.STL" />
            </geometry>
        </collision>
    </link>
    <joint name="r_hand_roll" type="continuous">
        <origin xyz="0 0 0" rpy="0 0 0" />
        <parent link="r_hand_pitch" />
        <child link="r_hand_roll" />
        <axis xyz="1 0 0" />
    </joint>
    <link name="l_leg_roll">
        <inertial>
            <origin xyz="-0.0111795086275655 -0.000123216790510347 -0.00147074190276802" rpy="0 0 0" />
            <mass value="0.379425755318659" />
            <inertia ixx="0.000304743319113934" ixy="2.4132837454244E-09" ixz="-1.61296145176274E-05" iyy="0.000772105186246157" iyz="3.09074100933869E-07" izz="0.000961637403412868" />
        </inertial>
        <visual>
            <origin xyz="0 0 0" rpy="0 0 0" />
            <geometry>
                <mesh filename="package://biped_gen/meshes/l_leg_roll.STL" />
            </geometry>
            <material name="">
                <color rgba="0.898039215686275 0.917647058823529 0.929411764705882 1" />
            </material>
        </visual>
        <collision>
            <origin xyz="0 0 0" rpy="0 0 0" />
            <geometry>
                <mesh filename="package://biped_gen/meshes/l_leg_roll.STL" />
            </geometry>
        </collision>
    </link>
    <joint name="l_leg_roll" type="continuous">
        <origin xyz="-0.00254758231249262 0.0869999999999998 -0.0660000000049238" rpy="0 0 0" />
        <parent link="base_link" />
        <child link="l_leg_roll" />
        <axis xyz="-1 0 0" />
    </joint>
    <link name="l_leg_yaw">
        <inertial>
            <origin xyz="-2.35778187231833E-05 0.057768207621115 -0.103929168930568" rpy="0 0 0" />
            <mass value="1.02872204907551" />
            <inertia ixx="0.00147762234553187" ixy="3.48522018944733E-07" ixz="-1.02364547910938E-06" iyy="0.00221142702467773" iyz="3.53567926256054E-05" izz="0.00129984253623211" />
        </inertial>
        <visual>
            <origin xyz="0 0 0" rpy="0 0 0" />
            <geometry>
                <mesh filename="package://biped_gen/meshes/l_leg_yaw.STL" />
            </geometry>
            <material name="">
                <color rgba="0.898039215686275 0.917647058823529 0.929411764705882 1" />
            </material>
        </visual>
        <collision>
            <origin xyz="0 0 0" rpy="0 0 0" />
            <geometry>
                <mesh filename="package://biped_gen/meshes/l_leg_yaw.STL" />
            </geometry>
        </collision>
    </link>
    <joint name="l_leg_yaw" type="continuous">
        <origin xyz="0 0 0" rpy="0 0 0" />
        <parent link="l_leg_roll" />
        <child link="l_leg_yaw" />
        <axis xyz="0 0 1" />
    </joint>
    <link name="l_leg_pitch">
        <inertial>
            <origin xyz="-0.0011694981769614 -0.0111795531459182 -0.100922019310959" rpy="0 0 0" />
            <mass value="2.07734202580432" />
            <inertia ixx="0.00754223938877161" ixy="-6.36664694004238E-05" ixz="9.50657330070212E-05" iyy="0.00802559652114804" iyz="2.26343904239653E-05" izz="0.00365760255777358" />
        </inertial>
        <visual>
            <origin xyz="0 0 0" rpy="0 0 0" />
            <geometry>
                <mesh filename="package://biped_gen/meshes/l_leg_pitch.STL" />
            </geometry>
            <material name="">
                <color rgba="0.898039215686275 0.917647058823529 0.929411764705882 1" />
            </material>
        </visual>
        <collision>
            <origin xyz="0 0 0" rpy="0 0 0" />
            <geometry>
                <mesh filename="package://biped_gen/meshes/l_leg_pitch.STL" />
            </geometry>
        </collision>
    </link>
    <joint name="l_leg_pitch" type="continuous">
        <origin xyz="0 0.025450000000002 -0.123449999999999" rpy="0 0 0" />
        <parent link="l_leg_yaw" />
        <child link="l_leg_pitch" />
        <axis xyz="0 1 0" />
    </joint>
    <link name="l_knee">
        <inertial>
            <origin xyz="0.00837415991732178 -1.3826294958233E-05 -0.140326741489414" rpy="0 0 0" />
            <mass value="1.44549323664959" />
            <inertia ixx="0.0110280659232287" ixy="1.8193609650388E-05" ixz="-0.000324492301007134" iyy="0.011282995858641" iyz="8.89496315136456E-05" izz="0.000857506252874573" />
        </inertial>
        <visual>
            <origin xyz="0 0 0" rpy="0 0 0" />
            <geometry>
                <mesh filename="package://biped_gen/meshes/l_knee.STL" />
            </geometry>
            <material name="">
                <color rgba="0.898039215686275 0.917647058823529 0.929411764705882 1" />
            </material>
        </visual>
        <collision>
            <origin xyz="0 0 0" rpy="0 0 0" />
            <geometry>
                <mesh filename="package://biped_gen/meshes/l_knee.STL" />
            </geometry>
        </collision>
    </link>
    <joint name="l_knee" type="continuous">
        <origin xyz="-0.010390161952608 0 -0.249783995753446" rpy="0 0 0" />
        <parent link="l_leg_pitch" />
        <child link="l_knee" />
        <axis xyz="0 1 0" />
    </joint>
    <link name="l_foot_pitch">
        <inertial>
            <origin xyz="-1.81202930832E-07 1.81202930812918E-07 0" rpy="0 0 0" />
            <mass value="0.00680556727254332" />
            <inertia ixx="5.13627197456046E-07" ixy="-2.2345571221277E-16" ixz="-2.99517054444242E-11" iyy="5.13627197456051E-07" iyz="-2.94871513305291E-11" izz="9.09837232073046E-07" />
        </inertial>
        <visual>
            <origin xyz="0 0 0" rpy="0 0 0" />
            <geometry>
                <mesh filename="package://biped_gen/meshes/l_foot_pitch.STL" />
            </geometry>
            <material name="">
                <color rgba="1 1 1 1" />
            </material>
        </visual>
        <collision>
            <origin xyz="0 0 0" rpy="0 0 0" />
            <geometry>
                <mesh filename="package://biped_gen/meshes/l_foot_pitch.STL" />
            </geometry>
        </collision>
    </link>
    <joint name="l_foot_pitch" type="continuous">
        <origin xyz="0 0 -0.346000000000004" rpy="0 0 0" />
        <parent link="l_knee" />
        <child link="l_foot_pitch" />
        <axis xyz="0 1 0" />
    </joint>
    <link name="l_foot_roll">
        <inertial>
            <origin xyz="0.00786618796284637 -8.14594110543077E-06 -0.0323276518434055" rpy="0 0 0" />
            <mass value="0.191216415778231" />
            <inertia ixx="0.000129574142247383" ixy="1.87464190291419E-08" ixz="3.6613974070797E-06" iyy="0.000315194751106857" iyz="3.63736673242767E-09" izz="0.000418024913490127" />
        </inertial>
        <visual>
            <origin xyz="0 0 0" rpy="0 0 0" />
            <geometry>
                <mesh filename="package://biped_gen/meshes/l_foot_roll.STL" />
            </geometry>
            <material name="">
                <color rgba="1 1 1 1" />
            </material>
        </visual>
        <collision>
            <origin xyz="0 0 0" rpy="0 0 0" />
            <geometry>
                <mesh filename="package://biped_gen/meshes/l_foot_roll.STL" />
            </geometry>
        </collision>
    </link>
    <joint name="l_foot_roll" type="continuous">
        <origin xyz="0 0 0" rpy="0 0 0" />
        <parent link="l_foot_pitch" />
        <child link="l_foot_roll" />
        <axis xyz="-1 0 0" />
    </joint>
    <link name="l_l_bar_y">
        <inertial>
            <origin xyz="-0.0172816855836413 0.00661593706720379 -4.41598945299937E-07" rpy="0 0 0" />
            <mass value="0.024194912013638" />
            <inertia ixx="3.02750697926575E-06" ixy="-1.66046578095266E-06" ixz="2.82260658835769E-10" iyy="1.6340380439564E-05" iyz="6.19121181411221E-11" izz="1.40552887097951E-05" />
        </inertial>
        <visual>
            <origin xyz="0 0 0" rpy="0 0 0" />
            <geometry>
                <mesh filename="package://biped_gen/meshes/l_l_bar_y.STL" />
            </geometry>
            <material name="">
                <color rgba="0.898039215686275 0.917647058823529 0.929411764705882 1" />
            </material>
        </visual>
        <collision>
            <origin xyz="0 0 0" rpy="0 0 0" />
            <geometry>
                <mesh filename="package://biped_gen/meshes/l_l_bar_y.STL" />
            </geometry>
        </collision>
    </link>
    <joint name="l_l_bar_y" type="continuous">
        <origin xyz="0 0.0260000000000038 -0.09" rpy="0 0 0" />
        <parent link="l_knee" />
        <child link="l_l_bar_y" />
        <axis xyz="0 1 0" />
    </joint>
    <link name="l_l_tendon">
        <inertial>
            <origin xyz="7.50976433122608E-08 -0.00107382527336489 -0.116415150677104" rpy="0 0 0" />
            <mass value="0.0723259190697974" />
            <inertia ixx="0.000407065580992204" ixy="-4.8491589649146E-12" ixz="5.8706757975535E-11" iyy="0.000405860828842815" iyz="-1.63254460253815E-07" izz="2.46503282882307E-06" />
        </inertial>
        <visual>
            <origin xyz="0 0 0" rpy="0 0 0" />
            <geometry>
                <mesh filename="package://biped_gen/meshes/l_l_tendon.STL" />
            </geometry>
            <material name="">
                <color rgba="0.898039215686275 0.917647058823529 0.929411764705882 1" />
            </material>
        </visual>
        <collision>
            <origin xyz="0 0 0" rpy="0 0 0" />
            <geometry>
                <mesh filename="package://biped_gen/meshes/l_l_tendon.STL" />
            </geometry>
        </collision>
    </link>
    <joint name="l_l_tendon" type="continuous">
        <origin xyz="-0.0579999999999961 0 0" rpy="0 0 0" />
        <parent link="l_l_bar_y" />
        <child link="l_l_tendon" />
        <axis xyz="0 -1 0" />
    </joint>
    <link name="l_r_bar">
        <inertial>
            <origin xyz="-0.0172816855836293 -0.0066159370672273 4.41598937306331E-07" rpy="0 0 0" />
            <mass value="0.0241949120136365" />
            <inertia ixx="3.02750697926557E-06" ixy="1.66046578095259E-06" ixz="-2.82260658798909E-10" iyy="1.63403804395638E-05" iyz="6.19121181994065E-11" izz="1.4055288709795E-05" />
        </inertial>
        <visual>
            <origin xyz="0 0 0" rpy="0 0 0" />
            <geometry>
                <mesh filename="package://biped_gen/meshes/l_r_bar.STL" />
            </geometry>
            <material name="">
                <color rgba="0.898039215686275 0.917647058823529 0.929411764705882 1" />
            </material>
        </visual>
        <collision>
            <origin xyz="0 0 0" rpy="0 0 0" />
            <geometry>
                <mesh filename="package://biped_gen/meshes/l_r_bar.STL" />
            </geometry>
        </collision>
    </link>
    <joint name="l_r_bar" type="continuous">
        <origin xyz="0 -0.0259999999999997 -0.153" rpy="0 0 0" />
        <parent link="l_knee" />
        <child link="l_r_bar" />
        <axis xyz="0 1 0" />
    </joint>
    <link name="l_r_tendon">
        <inertial>
            <origin xyz="9.88746583913125E-08 0.00109368385284707 -0.0855398908076652" rpy="0 0 0" />
            <mass value="0.0569965201570474" />
            <inertia ixx="0.000181317571889253" ixy="5.04945898327747E-12" ixz="5.97733856535807E-11" iyy="0.000180444606724358" iyz="1.22251624208646E-07" izz="1.95428817890955E-06" />
        </inertial>
        <visual>
            <origin xyz="0 0 0" rpy="0 0 0" />
            <geometry>
                <mesh filename="package://biped_gen/meshes/l_r_tendon.STL" />
            </geometry>
            <material name="">
                <color rgba="0.898039215686275 0.917647058823529 0.929411764705882 1" />
            </material>
        </visual>
        <collision>
            <origin xyz="0 0 0" rpy="0 0 0" />
            <geometry>
                <mesh filename="package://biped_gen/meshes/l_r_tendon.STL" />
            </geometry>
        </collision>
    </link>
    <joint name="l_r_tendon" type="continuous">
        <origin xyz="-0.0579999999999935 0 0" rpy="0 0 0" />
        <parent link="l_r_bar" />
        <child link="l_r_tendon" />
        <axis xyz="0 1 0" />
    </joint>
    <link name="r_leg_roll">
        <inertial>
            <origin xyz="-0.0111795086275655 -0.00012321679051229 -0.00147074190276809" rpy="0 0 0" />
            <mass value="0.379425755318659" />
            <inertia ixx="0.000304743319113934" ixy="2.41328374497633E-09" ixz="-1.61296145176275E-05" iyy="0.000772105186246158" iyz="3.09074100933869E-07" izz="0.000961637403412868" />
        </inertial>
        <visual>
            <origin xyz="0 0 0" rpy="0 0 0" />
            <geometry>
                <mesh filename="package://biped_gen/meshes/r_leg_roll.STL" />
            </geometry>
            <material name="">
                <color rgba="0.898039215686275 0.917647058823529 0.929411764705882 1" />
            </material>
        </visual>
        <collision>
            <origin xyz="0 0 0" rpy="0 0 0" />
            <geometry>
                <mesh filename="package://biped_gen/meshes/r_leg_roll.STL" />
            </geometry>
        </collision>
    </link>
    <joint name="r_leg_roll" type="continuous">
        <origin xyz="-0.00254758231249268 -0.0870000000000003 -0.0660000000049238" rpy="0 0 0" />
        <parent link="base_link" />
        <child link="r_leg_roll" />
        <axis xyz="-1 0 0" />
    </joint>
    <link name="r_leg_yaw">
        <inertial>
            <origin xyz="2.35778187267122E-05 -0.0577682076211163 -0.103929168930567" rpy="0 0 0" />
            <mass value="1.0287220490755" />
            <inertia ixx="0.00147762234553187" ixy="3.48522018945005E-07" ixz="1.02364547910872E-06" iyy="0.00221142702467772" iyz="-3.5356792625605E-05" izz="0.0012998425362321" />
        </inertial>
        <visual>
            <origin xyz="0 0 0" rpy="0 0 0" />
            <geometry>
                <mesh filename="package://biped_gen/meshes/r_leg_yaw.STL" />
            </geometry>
            <material name="">
                <color rgba="0.898039215686275 0.917647058823529 0.929411764705882 1" />
            </material>
        </visual>
        <collision>
            <origin xyz="0 0 0" rpy="0 0 0" />
            <geometry>
                <mesh filename="package://biped_gen/meshes/r_leg_yaw.STL" />
            </geometry>
        </collision>
    </link>
    <joint name="r_leg_yaw" type="continuous">
        <origin xyz="0 0 0" rpy="0 0 0" />
        <parent link="r_leg_roll" />
        <child link="r_leg_yaw" />
        <axis xyz="0 0 1" />
    </joint>
    <link name="r_leg_pitch">
        <inertial>
            <origin xyz="-0.00107020326176506 0.0113648232369035 -0.100928233384041" rpy="0 0 0" />
            <mass value="2.07088390013711" />
            <inertia ixx="0.00754830078233489" ixy="6.16605286514658E-05" ixz="9.77706972521779E-05" iyy="0.00803364959051972" iyz="-1.93085998051274E-05" izz="0.00366293826971374" />
        </inertial>
        <visual>
            <origin xyz="0 0 0" rpy="0 0 0" />
            <geometry>
                <mesh filename="package://biped_gen/meshes/r_leg_pitch.STL" />
            </geometry>
            <material name="">
                <color rgba="0.898039215686275 0.917647058823529 0.929411764705882 1" />
            </material>
        </visual>
        <collision>
            <origin xyz="0 0 0" rpy="0 0 0" />
            <geometry>
                <mesh filename="package://biped_gen/meshes/r_leg_pitch.STL" />
            </geometry>
        </collision>
    </link>
    <joint name="r_leg_pitch" type="continuous">
        <origin xyz="0 -0.0254500000000034 -0.123449999999998" rpy="0 0 0" />
        <parent link="r_leg_yaw" />
        <child link="r_leg_pitch" />
        <axis xyz="0 -1 0" />
    </joint>
    <link name="r_knee">
        <inertial>
            <origin xyz="0.00837373211586944 1.48731434937988E-05 -0.140326343934617" rpy="0 0 0" />
            <mass value="1.44559496259536" />
            <inertia ixx="0.0110283914378026" ixy="-1.81920907614259E-05" ixz="-0.000324488082680737" iyy="0.0112832978074819" iyz="-8.89800140166474E-05" izz="0.000857552224208578" />
        </inertial>
        <visual>
            <origin xyz="0 0 0" rpy="0 0 0" />
            <geometry>
                <mesh filename="package://biped_gen/meshes/r_knee.STL" />
            </geometry>
            <material name="">
                <color rgba="0.898039215686275 0.917647058823529 0.929411764705882 1" />
            </material>
        </visual>
        <collision>
            <origin xyz="0 0 0" rpy="0 0 0" />
            <geometry>
                <mesh filename="package://biped_gen/meshes/r_knee.STL" />
            </geometry>
        </collision>
    </link>
    <joint name="r_knee" type="continuous">
        <origin xyz="-0.0103901619526017 0 -0.249783995753447" rpy="0 0 0" />
        <parent link="r_leg_pitch" />
        <child link="r_knee" />
        <axis xyz="0 1 0" />
    </joint>
    <link name="r_foot_pitch">
        <inertial>
            <origin xyz="-1.81202926713767E-07 -1.81202930812918E-07 1.11022302462516E-16" rpy="0 0 0" />
            <mass value="0.00680556727254334" />
            <inertia ixx="5.1362719745605E-07" ixy="2.2345565786124E-16" ixz="2.9487151330554E-11" iyy="5.13627197456047E-07" iyz="-2.99517054442681E-11" izz="9.09837232073046E-07" />
        </inertial>
        <visual>
            <origin xyz="0 0 0" rpy="0 0 0" />
            <geometry>
                <mesh filename="package://biped_gen/meshes/r_foot_pitch.STL" />
            </geometry>
            <material name="">
                <color rgba="1 1 1 1" />
            </material>
        </visual>
        <collision>
            <origin xyz="0 0 0" rpy="0 0 0" />
            <geometry>
                <mesh filename="package://biped_gen/meshes/r_foot_pitch.STL" />
            </geometry>
        </collision>
    </link>
    <joint name="r_foot_pitch" type="continuous">
        <origin xyz="0 0 -0.345999999999999" rpy="0 0 0" />
        <parent link="r_knee" />
        <child link="r_foot_pitch" />
        <axis xyz="0 1 0" />
    </joint>
    <link name="r_foot_roll">
        <inertial>
            <origin xyz="0.00786618796128613 -8.14594000766999E-06 -0.0323276518432707" rpy="0 0 0" />
            <mass value="0.19121641578482" />
            <inertia ixx="0.000129574142254522" ixy="1.87464121723204E-08" ixz="3.66139740707046E-06" iyy="0.000315194751113543" iyz="3.63736673345242E-09" izz="0.000418024913503951" />
        </inertial>
        <visual>
            <origin xyz="0 0 0" rpy="0 0 0" />
            <geometry>
                <mesh filename="package://biped_gen/meshes/r_foot_roll.STL" />
            </geometry>
            <material name="">
                <color rgba="1 1 1 1" />
            </material>
        </visual>
        <collision>
            <origin xyz="0 0 0" rpy="0 0 0" />
            <geometry>
                <mesh filename="package://biped_gen/meshes/r_foot_roll.STL" />
            </geometry>
        </collision>
    </link>
    <joint name="r_foot_roll" type="continuous">
        <origin xyz="0 0 0" rpy="0 0 0" />
        <parent link="r_foot_pitch" />
        <child link="r_foot_roll" />
        <axis xyz="-1 0 0" />
    </joint>
    <link name="r_l_bar">
        <inertial>
            <origin xyz="-0.0172817199747868 0.00661593008078076 4.61156707043386E-07" rpy="0 0 0" />
            <mass value="0.0241948685329019" />
            <inertia ixx="3.02750059467426E-06" ixy="-1.6604620507784E-06" ixz="-2.92284767564349E-10" iyy="1.63403563665509E-05" iyz="-6.3945045287444E-11" izz="1.40552694993396E-05" />
        </inertial>
        <visual>
            <origin xyz="0 0 0" rpy="0 0 0" />
            <geometry>
                <mesh filename="package://biped_gen/meshes/r_l_bar.STL" />
            </geometry>
            <material name="">
                <color rgba="1 1 1 1" />
            </material>
        </visual>
        <collision>
            <origin xyz="0 0 0" rpy="0 0 0" />
            <geometry>
                <mesh filename="package://biped_gen/meshes/r_l_bar.STL" />
            </geometry>
        </collision>
    </link>
    <joint name="r_l_bar" type="continuous">
        <origin xyz="0 0.0260000000000006 -0.153" rpy="0 0 0" />
        <parent link="r_knee" />
        <child link="r_l_bar" />
        <axis xyz="0 -1 0" />
    </joint>
    <link name="r_l_tendon">
        <inertial>
            <origin xyz="-9.88747644453669E-08 -0.00109368385287011 -0.0855398908076592" rpy="0 0 0" />
            <mass value="0.0569965201570475" />
            <inertia ixx="0.000181317571889253" ixy="5.04945881821743E-12" ixz="-5.97736308806424E-11" iyy="0.000180444606724358" iyz="-1.22251624208626E-07" izz="1.95428817890956E-06" />
        </inertial>
        <visual>
            <origin xyz="0 0 0" rpy="0 0 0" />
            <geometry>
                <mesh filename="package://biped_gen/meshes/r_l_tendon.STL" />
            </geometry>
            <material name="">
                <color rgba="0.898039215686275 0.917647058823529 0.929411764705882 1" />
            </material>
        </visual>
        <collision>
            <origin xyz="0 0 0" rpy="0 0 0" />
            <geometry>
                <mesh filename="package://biped_gen/meshes/r_l_tendon.STL" />
            </geometry>
        </collision>
    </link>
    <joint name="r_l_tendon" type="continuous">
        <origin xyz="-0.0580000000000044 0 0" rpy="0 0 0" />
        <parent link="r_l_bar" />
        <child link="r_l_tendon" />
        <axis xyz="0 -1 0" />
    </joint>
    <link name="r_r_bar">
        <inertial>
            <origin xyz="-0.0172817199747909 -0.0066159300808061 -4.61156706599297E-07" rpy="0 0 0" />
            <mass value="0.0241948685329001" />
            <inertia ixx="3.02750059467416E-06" ixy="1.66046205077837E-06" ixz="2.92284767874824E-10" iyy="1.63403563665505E-05" iyz="-6.39450453935481E-11" izz="1.40552694993395E-05" />
        </inertial>
        <visual>
            <origin xyz="0 0 0" rpy="0 0 0" />
            <geometry>
                <mesh filename="package://biped_gen/meshes/r_r_bar.STL" />
            </geometry>
            <material name="">
                <color rgba="1 1 1 1" />
            </material>
        </visual>
        <collision>
            <origin xyz="0 0 0" rpy="0 0 0" />
            <geometry>
                <mesh filename="package://biped_gen/meshes/r_r_bar.STL" />
            </geometry>
        </collision>
    </link>
    <joint name="r_r_bar" type="continuous">
        <origin xyz="0 -0.0259999999999875 -0.09" rpy="0 0 0" />
        <parent link="r_knee" />
        <child link="r_r_bar" />
        <axis xyz="0 -1 0" />
    </joint>
    <link name="r_r_tendon">
        <inertial>
            <origin xyz="7.55754646364348E-08 0.00107382573957718 -0.116415142605242" rpy="0 0 0" />
            <mass value="0.0723258862757365" />
            <inertia ixx="0.000407065577150581" ixy="4.88369892924843E-12" ixz="5.90598728281556E-11" iyy="0.000405860824979807" iyz="1.63254813219836E-07" izz="2.46503277229997E-06" />
        </inertial>
        <visual>
            <origin xyz="0 0 0" rpy="0 0 0" />
            <geometry>
                <mesh filename="package://biped_gen/meshes/r_r_tendon.STL" />
            </geometry>
            <material name="">
                <color rgba="0.898039215686275 0.917647058823529 0.929411764705882 1" />
            </material>
        </visual>
        <collision>
            <origin xyz="0 0 0" rpy="0 0 0" />
            <geometry>
                <mesh filename="package://biped_gen/meshes/r_r_tendon.STL" />
            </geometry>
        </collision>
    </link>
    <joint name="r_r_tendon" type="continuous">
        <origin xyz="-0.057999999999996 0 0" rpy="0 0 0" />
        <parent link="r_r_bar" />
        <child link="r_r_tendon" />
        <axis xyz="0 1 0" />
    </joint>
    <link name="head_yaw">
        <inertial>
            <origin xyz="-0.000116065796709808 0.0034128323068932 -0.00762227943283844" rpy="0 0 0" />
            <mass value="0.0876587232040551" />
            <inertia ixx="5.29184226374934E-05" ixy="-5.55749298909922E-08" ixz="2.93674313773848E-07" iyy="7.69981959753033E-05" iyz="-9.22993448844536E-06" izz="5.31017800814282E-05" />
        </inertial>
        <visual>
            <origin xyz="0 0 0" rpy="0 0 0" />
            <geometry>
                <mesh filename="package://biped_gen/meshes/head_yaw.STL" />
            </geometry>
            <material name="">
                <color rgba="1 1 1 1" />
            </material>
        </visual>
        <collision>
            <origin xyz="0 0 0" rpy="0 0 0" />
            <geometry>
                <mesh filename="package://biped_gen/meshes/head_yaw.STL" />
            </geometry>
        </collision>
    </link>
    <joint name="head_yaw" type="continuous">
        <origin xyz="-0.0175475823124929 0 0.499400000000373" rpy="0 0 0" />
        <parent link="base_link" />
        <child link="head_yaw" />
        <axis xyz="0 0 -1" />
    </joint>
    <link name="head_pitch">
        <inertial>
            <origin xyz="0.0108076765997382 -0.00100494759438116 0.0523165975702761" rpy="0 0 0" />
            <mass value="0.348142076778321" />
            <inertia ixx="0.000904070873567588" ixy="1.57558780381525E-06" ixz="0.000295083531658369" iyy="0.000957585537827453" iyz="-9.61289176090941E-06" izz="0.00114051835139601" />
        </inertial>
        <visual>
            <origin xyz="0 0 0" rpy="0 0 0" />
            <geometry>
                <mesh filename="package://biped_gen/meshes/head_pitch.STL" />
            </geometry>
            <material name="">
                <color rgba="1 1 1 1" />
            </material>
        </visual>
        <collision>
            <origin xyz="0 0 0" rpy="0 0 0" />
            <geometry>
                <mesh filename="package://biped_gen/meshes/head_pitch.STL" />
            </geometry>
        </collision>
    </link>
    <joint name="head_pitch" type="continuous">
        <origin xyz="0 0 0" rpy="0 0 0" />
        <parent link="head_yaw" />
        <child link="head_pitch" />
        <axis xyz="0 -1 0" />
    </joint>
    <transmission name="trans_l_arm_pitch">
        <type>transmission_interface/SimpleTransmission</type>
        <joint name="l_arm_pitch">
            <hardwareInterface>hardware_interface/EffortJointInterface</hardwareInterface>
        </joint>
        <actuator name="l_arm_pitch_motor">
            <hardwareInterface>hardware_interface/EffortJointInterface</hardwareInterface>
            <mechanicalReduction>1</mechanicalReduction>
        </actuator>
    </transmission>
    <transmission name="trans_l_arm_roll">
        <type>transmission_interface/SimpleTransmission</type>
        <joint name="l_arm_roll">
            <hardwareInterface>hardware_interface/EffortJointInterface</hardwareInterface>
        </joint>
        <actuator name="l_arm_roll_motor">
            <hardwareInterface>hardware_interface/EffortJointInterface</hardwareInterface>
            <mechanicalReduction>1</mechanicalReduction>
        </actuator>
    </transmission>
    <transmission name="trans_l_arm_yaw">
        <type>transmission_interface/SimpleTransmission</type>
        <joint name="l_arm_yaw">
            <hardwareInterface>hardware_interface/EffortJointInterface</hardwareInterface>
        </joint>
        <actuator name="l_arm_yaw_motor">
            <hardwareInterface>hardware_interface/EffortJointInterface</hardwareInterface>
            <mechanicalReduction>1</mechanicalReduction>
        </actuator>
    </transmission>
    <transmission name="trans_l_forearm_pitch">
        <type>transmission_interface/SimpleTransmission</type>
        <joint name="l_forearm_pitch">
            <hardwareInterface>hardware_interface/EffortJointInterface</hardwareInterface>
        </joint>
        <actuator name="l_forearm_pitch_motor">
            <hardwareInterface>hardware_interface/EffortJointInterface</hardwareInterface>
            <mechanicalReduction>1</mechanicalReduction>
        </actuator>
    </transmission>
    <transmission name="trans_l_hand_yaw">
        <type>transmission_interface/SimpleTransmission</type>
        <joint name="l_hand_yaw">
            <hardwareInterface>hardware_interface/EffortJointInterface</hardwareInterface>
        </joint>
        <actuator name="l_hand_yaw_motor">
            <hardwareInterface>hardware_interface/EffortJointInterface</hardwareInterface>
            <mechanicalReduction>1</mechanicalReduction>
        </actuator>
    </transmission>
    <transmission name="trans_l_hand_pitch">
        <type>transmission_interface/SimpleTransmission</type>
        <joint name="l_hand_pitch">
            <hardwareInterface>hardware_interface/EffortJointInterface</hardwareInterface>
        </joint>
        <actuator name="l_hand_pitch_motor">
            <hardwareInterface>hardware_interface/EffortJointInterface</hardwareInterface>
            <mechanicalReduction>1</mechanicalReduction>
        </actuator>
    </transmission>
    <transmission name="trans_l_hand_roll">
        <type>transmission_interface/SimpleTransmission</type>
        <joint name="l_hand_roll">
            <hardwareInterface>hardware_interface/EffortJointInterface</hardwareInterface>
        </joint>
        <actuator name="l_hand_roll_motor">
            <hardwareInterface>hardware_interface/EffortJointInterface</hardwareInterface>
            <mechanicalReduction>1</mechanicalReduction>
        </actuator>
    </transmission>
    <transmission name="trans_r_arm_pitch">
        <type>transmission_interface/SimpleTransmission</type>
        <joint name="r_arm_pitch">
            <hardwareInterface>hardware_interface/EffortJointInterface</hardwareInterface>
        </joint>
        <actuator name="r_arm_pitch_motor">
            <hardwareInterface>hardware_interface/EffortJointInterface</hardwareInterface>
            <mechanicalReduction>1</mechanicalReduction>
        </actuator>
    </transmission>
    <transmission name="trans_r_arm_roll">
        <type>transmission_interface/SimpleTransmission</type>
        <joint name="r_arm_roll">
            <hardwareInterface>hardware_interface/EffortJointInterface</hardwareInterface>
        </joint>
        <actuator name="r_arm_roll_motor">
            <hardwareInterface>hardware_interface/EffortJointInterface</hardwareInterface>
            <mechanicalReduction>1</mechanicalReduction>
        </actuator>
    </transmission>
    <transmission name="trans_r_arm_yaw">
        <type>transmission_interface/SimpleTransmission</type>
        <joint name="r_arm_yaw">
            <hardwareInterface>hardware_interface/EffortJointInterface</hardwareInterface>
        </joint>
        <actuator name="r_arm_yaw_motor">
            <hardwareInterface>hardware_interface/EffortJointInterface</hardwareInterface>
            <mechanicalReduction>1</mechanicalReduction>
        </actuator>
    </transmission>
    <transmission name="trans_r_forearm_pitch">
        <type>transmission_interface/SimpleTransmission</type>
        <joint name="r_forearm_pitch">
            <hardwareInterface>hardware_interface/EffortJointInterface</hardwareInterface>
        </joint>
        <actuator name="r_forearm_pitch_motor">
            <hardwareInterface>hardware_interface/EffortJointInterface</hardwareInterface>
            <mechanicalReduction>1</mechanicalReduction>
        </actuator>
    </transmission>
    <transmission name="trans_r_hand_yaw">
        <type>transmission_interface/SimpleTransmission</type>
        <joint name="r_hand_yaw">
            <hardwareInterface>hardware_interface/EffortJointInterface</hardwareInterface>
        </joint>
        <actuator name="r_hand_yaw_motor">
            <hardwareInterface>hardware_interface/EffortJointInterface</hardwareInterface>
            <mechanicalReduction>1</mechanicalReduction>
        </actuator>
    </transmission>
    <transmission name="trans_r_hand_pitch">
        <type>transmission_interface/SimpleTransmission</type>
        <joint name="r_hand_pitch">
            <hardwareInterface>hardware_interface/EffortJointInterface</hardwareInterface>
        </joint>
        <actuator name="r_hand_pitch_motor">
            <hardwareInterface>hardware_interface/EffortJointInterface</hardwareInterface>
            <mechanicalReduction>1</mechanicalReduction>
        </actuator>
    </transmission>
    <transmission name="trans_r_hand_roll">
        <type>transmission_interface/SimpleTransmission</type>
        <joint name="r_hand_roll">
            <hardwareInterface>hardware_interface/EffortJointInterface</hardwareInterface>
        </joint>
        <actuator name="r_hand_roll_motor">
            <hardwareInterface>hardware_interface/EffortJointInterface</hardwareInterface>
            <mechanicalReduction>1</mechanicalReduction>
        </actuator>
    </transmission>
    <transmission name="trans_l_leg_roll">
        <type>transmission_interface/SimpleTransmission</type>
        <joint name="l_leg_roll">
            <hardwareInterface>hardware_interface/EffortJointInterface</hardwareInterface>
        </joint>
        <actuator name="l_leg_roll_motor">
            <hardwareInterface>hardware_interface/EffortJointInterface</hardwareInterface>
            <mechanicalReduction>1</mechanicalReduction>
        </actuator>
    </transmission>
    <transmission name="trans_l_leg_yaw">
        <type>transmission_interface/SimpleTransmission</type>
        <joint name="l_leg_yaw">
            <hardwareInterface>hardware_interface/EffortJointInterface</hardwareInterface>
        </joint>
        <actuator name="l_leg_yaw_motor">
            <hardwareInterface>hardware_interface/EffortJointInterface</hardwareInterface>
            <mechanicalReduction>1</mechanicalReduction>
        </actuator>
    </transmission>
    <transmission name="trans_l_leg_pitch">
        <type>transmission_interface/SimpleTransmission</type>
        <joint name="l_leg_pitch">
            <hardwareInterface>hardware_interface/EffortJointInterface</hardwareInterface>
        </joint>
        <actuator name="l_leg_pitch_motor">
            <hardwareInterface>hardware_interface/EffortJointInterface</hardwareInterface>
            <mechanicalReduction>1</mechanicalReduction>
        </actuator>
    </transmission>
    <transmission name="trans_l_knee">
        <type>transmission_interface/SimpleTransmission</type>
        <joint name="l_knee">
            <hardwareInterface>hardware_interface/EffortJointInterface</hardwareInterface>
        </joint>
        <actuator name="l_knee_motor">
            <hardwareInterface>hardware_interface/EffortJointInterface</hardwareInterface>
            <mechanicalReduction>1</mechanicalReduction>
        </actuator>
    </transmission>
    <transmission name="trans_l_foot_pitch">
        <type>transmission_interface/SimpleTransmission</type>
        <joint name="l_foot_pitch">
            <hardwareInterface>hardware_interface/EffortJointInterface</hardwareInterface>
        </joint>
        <actuator name="l_foot_pitch_motor">
            <hardwareInterface>hardware_interface/EffortJointInterface</hardwareInterface>
            <mechanicalReduction>1</mechanicalReduction>
        </actuator>
    </transmission>
    <transmission name="trans_l_foot_roll">
        <type>transmission_interface/SimpleTransmission</type>
        <joint name="l_foot_roll">
            <hardwareInterface>hardware_interface/EffortJointInterface</hardwareInterface>
        </joint>
        <actuator name="l_foot_roll_motor">
            <hardwareInterface>hardware_interface/EffortJointInterface</hardwareInterface>
            <mechanicalReduction>1</mechanicalReduction>
        </actuator>
    </transmission>
    <transmission name="trans_l_l_bar_y">
        <type>transmission_interface/SimpleTransmission</type>
        <joint name="l_l_bar_y">
            <hardwareInterface>hardware_interface/EffortJointInterface</hardwareInterface>
        </joint>
        <actuator name="l_l_bar_y_motor">
            <hardwareInterface>hardware_interface/EffortJointInterface</hardwareInterface>
            <mechanicalReduction>1</mechanicalReduction>
        </actuator>
    </transmission>
    <transmission name="trans_l_l_tendon">
        <type>transmission_interface/SimpleTransmission</type>
        <joint name="l_l_tendon">
            <hardwareInterface>hardware_interface/EffortJointInterface</hardwareInterface>
        </joint>
        <actuator name="l_l_tendon_motor">
            <hardwareInterface>hardware_interface/EffortJointInterface</hardwareInterface>
            <mechanicalReduction>1</mechanicalReduction>
        </actuator>
    </transmission>
    <transmission name="trans_l_r_bar">
        <type>transmission_interface/SimpleTransmission</type>
        <joint name="l_r_bar">
            <hardwareInterface>hardware_interface/EffortJointInterface</hardwareInterface>
        </joint>
        <actuator name="l_r_bar_motor">
            <hardwareInterface>hardware_interface/EffortJointInterface</hardwareInterface>
            <mechanicalReduction>1</mechanicalReduction>
        </actuator>
    </transmission>
    <transmission name="trans_l_r_tendon">
        <type>transmission_interface/SimpleTransmission</type>
        <joint name="l_r_tendon">
            <hardwareInterface>hardware_interface/EffortJointInterface</hardwareInterface>
        </joint>
        <actuator name="l_r_tendon_motor">
            <hardwareInterface>hardware_interface/EffortJointInterface</hardwareInterface>
            <mechanicalReduction>1</mechanicalReduction>
        </actuator>
    </transmission>
    <transmission name="trans_r_leg_roll">
        <type>transmission_interface/SimpleTransmission</type>
        <joint name="r_leg_roll">
            <hardwareInterface>hardware_interface/EffortJointInterface</hardwareInterface>
        </joint>
        <actuator name="r_leg_roll_motor">
            <hardwareInterface>hardware_interface/EffortJointInterface</hardwareInterface>
            <mechanicalReduction>1</mechanicalReduction>
        </actuator>
    </transmission>
    <transmission name="trans_r_leg_yaw">
        <type>transmission_interface/SimpleTransmission</type>
        <joint name="r_leg_yaw">
            <hardwareInterface>hardware_interface/EffortJointInterface</hardwareInterface>
        </joint>
        <actuator name="r_leg_yaw_motor">
            <hardwareInterface>hardware_interface/EffortJointInterface</hardwareInterface>
            <mechanicalReduction>1</mechanicalReduction>
        </actuator>
    </transmission>
    <transmission name="trans_r_leg_pitch">
        <type>transmission_interface/SimpleTransmission</type>
        <joint name="r_leg_pitch">
            <hardwareInterface>hardware_interface/EffortJointInterface</hardwareInterface>
        </joint>
        <actuator name="r_leg_pitch_motor">
            <hardwareInterface>hardware_interface/EffortJointInterface</hardwareInterface>
            <mechanicalReduction>1</mechanicalReduction>
        </actuator>
    </transmission>
    <transmission name="trans_r_knee">
        <type>transmission_interface/SimpleTransmission</type>
        <joint name="r_knee">
            <hardwareInterface>hardware_interface/EffortJointInterface</hardwareInterface>
        </joint>
        <actuator name="r_knee_motor">
            <hardwareInterface>hardware_interface/EffortJointInterface</hardwareInterface>
            <mechanicalReduction>1</mechanicalReduction>
        </actuator>
    </transmission>
    <transmission name="trans_r_foot_pitch">
        <type>transmission_interface/SimpleTransmission</type>
        <joint name="r_foot_pitch">
            <hardwareInterface>hardware_interface/EffortJointInterface</hardwareInterface>
        </joint>
        <actuator name="r_foot_pitch_motor">
            <hardwareInterface>hardware_interface/EffortJointInterface</hardwareInterface>
            <mechanicalReduction>1</mechanicalReduction>
        </actuator>
    </transmission>
    <transmission name="trans_r_foot_roll">
        <type>transmission_interface/SimpleTransmission</type>
        <joint name="r_foot_roll">
            <hardwareInterface>hardware_interface/EffortJointInterface</hardwareInterface>
        </joint>
        <actuator name="r_foot_roll_motor">
            <hardwareInterface>hardware_interface/EffortJointInterface</hardwareInterface>
            <mechanicalReduction>1</mechanicalReduction>
        </actuator>
    </transmission>
    <transmission name="trans_r_l_bar">
        <type>transmission_interface/SimpleTransmission</type>
        <joint name="r_l_bar">
            <hardwareInterface>hardware_interface/EffortJointInterface</hardwareInterface>
        </joint>
        <actuator name="r_l_bar_motor">
            <hardwareInterface>hardware_interface/EffortJointInterface</hardwareInterface>
            <mechanicalReduction>1</mechanicalReduction>
        </actuator>
    </transmission>
    <transmission name="trans_r_l_tendon">
        <type>transmission_interface/SimpleTransmission</type>
        <joint name="r_l_tendon">
            <hardwareInterface>hardware_interface/EffortJointInterface</hardwareInterface>
        </joint>
        <actuator name="r_l_tendon_motor">
            <hardwareInterface>hardware_interface/EffortJointInterface</hardwareInterface>
            <mechanicalReduction>1</mechanicalReduction>
        </actuator>
    </transmission>
    <transmission name="trans_r_r_bar">
        <type>transmission_interface/SimpleTransmission</type>
        <joint name="r_r_bar">
            <hardwareInterface>hardware_interface/EffortJointInterface</hardwareInterface>
        </joint>
        <actuator name="r_r_bar_motor">
            <hardwareInterface>hardware_interface/EffortJointInterface</hardwareInterface>
            <mechanicalReduction>1</mechanicalReduction>
        </actuator>
    </transmission>
    <transmission name="trans_r_r_tendon">
        <type>transmission_interface/SimpleTransmission</type>
        <joint name="r_r_tendon">
            <hardwareInterface>hardware_interface/EffortJointInterface</hardwareInterface>
        </joint>
        <actuator name="r_r_tendon_motor">
            <hardwareInterface>hardware_interface/EffortJointInterface</hardwareInterface>
            <mechanicalReduction>1</mechanicalReduction>
        </actuator>
    </transmission>
    <transmission name="trans_head_yaw">
        <type>transmission_interface/SimpleTransmission</type>
        <joint name="head_yaw">
            <hardwareInterface>hardware_interface/EffortJointInterface</hardwareInterface>
        </joint>
        <actuator name="head_yaw_motor">
            <hardwareInterface>hardware_interface/EffortJointInterface</hardwareInterface>
            <mechanicalReduction>1</mechanicalReduction>
        </actuator>
    </transmission>
    <transmission name="trans_head_pitch">
        <type>transmission_interface/SimpleTransmission</type>
        <joint name="head_pitch">
            <hardwareInterface>hardware_interface/EffortJointInterface</hardwareInterface>
        </joint>
        <actuator name="head_pitch_motor">
            <hardwareInterface>hardware_interface/EffortJointInterface</hardwareInterface>
            <mechanicalReduction>1</mechanicalReduction>
        </actuator>
    </transmission>
    <gazebo>
        <plugin name="gazebo_ros_control">
            <robotNamespace>/</robotNamespace>
        </plugin>
    </gazebo>
</robot>

